Workbook

Sheet Readme
A1: Document History
A2: Name of the Artifact | B2: TCS Security Design Review Checklist
A3: Version | B3: 4.0
A4: Release Date | B4: 45888
A6: Revision History
A7: Date | B7: Release No. | C7: Remarks
A8: 43466 | B8: 1.0 | C8: Formal Release of the document
A9: 45075 | B9: 2.0 | C9: Objective based questions for the security quality characteristics.
A10: 45117 | B10: 3.0 | C10: Added internet and intranet facing option under Asset Info tab and added the relevant changes in the checklist and report tab.
A11: 45888 | B11: 4.0 | C11: Added Gen AI security design guidelines
A12: © Copyright [2023], Tata Consultancy Services Limited. All Rights Reserved. Document ID CGKD009336 Unauthorized access, copying, replication, distribution, transmission, modification, adaptation or translation or use without express written permission is prohibited.
A15: Usage Guidelines
A16: • Asset details to be filled by the asset team in the Asset Info sheet. Answer the questions related to the asset in the Contextual Questions table. • Checklist sheet consists of all the line items that need to be addressed and the report sheet comprises the overall review report including the approval status. •The Applicability column in the Checklist sheet shows whether that particular line item is applicable or not; if it is 'Yes', then the asset team needs to select an appropriate Option (column F) from the drop down and if it is 'No' or if a row is grayed out it is not applicable and thus, need not be answered. •If the asset team selects the Option 'Yes' for any line item where Security Checkpoints is 'Others' or selects the Option 'No' for any line item that recommends something, they have to enter their comments mandatorily in the respective column; else the comments are optional. •If the asset team wants to reset the value in the Options column, they can simply delete the content in the options column. •Auto Approval column indicates whether that particular line item is eligible for auto approval or not. Y-indicates the line item is auto-approved and N not auto-approved. • Document Naming Convention: <TiparID of the asset>_Security_Design_Review_checklist.xlsx

Sheet Asset Info
A1: Asset TIPAR ID | B1: Tipar-ID
A2: Asset Information
A3: Asset Name & Version
A7: Contextual Questions
A8: Technology used
A9: Internet/Intranet facing
A10: Is it a multi-role application?
A11: Is the application dealing with Gen AI ? | B11: No | C11: =IF(B11="Yes","Please fill Gen AI Audit Sheet along with regular checklist","")
D45: =IF('Asset Info'!B8="Java","",IF('Asset Info'!B8="Python","",""))

Sheet Checklist
A1: Authentication and Password Management
A2: NFR | B2: Category | C2: Radio Options | D2: Security Checkpoints | E2: Applicability | F2: Option | G2: Remarks | H2: Application Team comments | I2: Reviewer Comments | J2: Auto Approval | K2: Conditional Warnings
A3: 1 | B3: Strong Password Policy | C3: 1 | D3: Does the application connects to customer SSO/LDAP/Identity & Access Management? | E3: =IF(COUNTIF(F4:F6,"Yes")>0,"No","Yes") -> Yes | F3: No | G3: =IF(F3="Yes","The application connects to customer SSO/LDAP/Identity & Access Management and hence no password policy managed within the application.","") | H3: no | J3: =IF(F3="Yes","Y","N") -> N
C4: 2 | D4: Is the application only a desktop application or a backend application and available as services without user authentication? | E4: =IF(OR(F3="Yes",COUNTIF(F5:F6,"Yes")>0),"No","Yes") -> Yes | G4: =IF(F4="Yes","The application is a backend application and do not have any password policy managed.","") | H4: no | J4: =IF(F4="Yes","Y","N") -> N
C5: 3 | D5: Has a strong password policy been implemented depending on the business requirements? | E5: =IF(OR(COUNTIF(F3:F4,"Yes")>0,F6="Yes"),"No","Yes") -> Yes | H5: Partially. The application enforces a minimum of 12 characters with uppercase, lowercase, numeric, and special characters; it also prevents inclusion of the user ID. Passwords are salted and hashed using PBKDF2-HMAC-SHA256 with 600,000 iterations. However, password history, expiry, breached-password screening, failed-login lockout, and rate limiting are not currently implemented and must be aligned with the organization’s password policy before production. | J5: =J7 -> N
C6: 4 | D6: Others | E6: =IF(COUNTIF(F3:F5,"Yes")>0,"No","Yes") -> Yes | J6: N | K6: =IF(AND(F6="Yes",ISBLANK(H6)),"Please enter your comments","")
C7: 3.1 | D7: Is the password policy configurable? | E7: =IF(F5="Yes","Yes","No") -> No | G7: =IF(OR(F7="No",F7="NA"),"Recommend to have password policy as configurable with min and max characters, 1 special character, 1 digit, atleast 1 upper case and 1 lower case letter. It should not allow to set last 5 passwords and force the user to reset the password periodically","") | H7: Partially implemented. The password policy is defined in backend code but is not configurable through application settings or environment variables. | J7: =J8 -> N | K7: =IF(AND(OR(F7="No",F7="NA"),ISBLANK(H7)),"Please enter your comments","")
C8: 3.1.1 | D8: =IF('Asset Info'!B9="Internet",CONCAT("Does the password policy consist of the following? Min length 8 to 12 characters, Max Length 50 to 64 characters, Atleast 1 upper case letter, Atleast 1 lower case letter, Atleast 1 digit, Atleast 1 special character,"," Password expiry after 30 or 60 days, Last five passwords are not allowed to be used while resetting the password."),CONCAT("Does the password policy consist of the following? Min length 8 to 12 characters, Max Length 50 to 64 characters,", "Atleast 1 upper case letter, Atleast 1 lower case letter, Atleast 1 digit, Atleast 1 special character" )) -> Does the password policy consist of the following? Min length 8 to 12 characters, Max Length 50 to 64 characters,Atleast 1 upper case letter, Atleast 1 lower case letter, Atleast 1 digit, Atleast 1 special character | E8: =IF(AND(F5="Yes",F7="Yes"),"Yes","No") -> No | G8: =IF(F8="Yes","Password Policy is configurable for min and max length and it contains atleast 1 special charcater, 1 digit, 1 upper case and 1 lower case character. It will not allow to set last 5 passwords and force the user to reset the password periodically.",IF(OR(F8="No",F8="NA"),"Recommend to have password policy as configurable with min and max characters, 1 special character, 1 digit, atleast 1 upper case and 1 lower case letter. It should not allow to set last 5 passwords and force the user to reset the password periodically","")) | H8: Partially implemented. Passwords require a minimum of 12 characters, uppercase, lowercase, digit, and special character. Passwords cannot contain the user ID. The configured maximum length is 128 characters, not 50–64. | J8: =IF(F8="Yes","Y","N") -> N | K8: =IF(AND(OR(F8="No",F8="NA"),ISBLANK(H8)),"Please enter your comments","")
A9: 2 | B9: Secure storage of credentials | C9: 1 | D9: =IF(OR(F3="Yes",F4="Yes"),"NA","Does the application store user credentials in DB by salting and hashing it?") -> Does the application store user credentials in DB by salting and hashing it? | E9: =IF(D9<>"NA","Yes","No") -> Yes | G9: =IF(OR(F9="No",F9="NA"),"Recommend to have store application user credenatials in DB by salting and hashing it using slow hashing algorithms like scrypt/bcrypt/PBKDF2WithHMACSHA256.PBKDF2WithHMACSHA512/Argon2id.","") | H9: Yes. The application stores passwords in the database only as salted hashes. It uses a unique cryptographically generated 16-byte salt for each password and PBKDF2-HMAC-SHA256 with 600,000 iterations. Plaintext passwords and reusable password credentials are not stored in the database. | J9: =IF(E9="No","Y",IF(OR(F9="No",F9="NA"),"N",J10)) -> N | K9: =IF(AND(OR(F9="No",F9="NA"),ISBLANK(H9)),"Please enter your comments","")
C10: 1.1 | D10: Does the application uses slow hashing algorithms like scrypt/bcrypt/PBKDF2WithHMACSHA256/PBKDF2WithHMACSHA512/Argon2id? | E10: =IF(F9="Yes","Yes","No") -> No | G10: =IF(F10="Yes","Application stores the user passwords in DB by salting and hashing it using slow hashing algorithms.",IF(OR(F10="No",F10="NA"),"Application stores the user passwords in DB by salting and hashing it. Recommend to use slow hashing algorithms like scrypt/bcrypt/PBKDF2WithHMACSHA256.PBKDF2WithHMACSHA512/Argon2id.","")) | H10: Implemented. User passwords are hashed using PBKDF2-HMAC-SHA256 with 600,000 iterations and a unique cryptographically random 16-byte salt. Password verification uses constant-time comparison. | J10: =IF(F10="Yes","Y","N") -> N | K10: =IF(AND(OR(F10="No",F10="NA"),ISBLANK(H10)),"Please enter your comments","")
A11: 3 | B11: Unique Id for each user | C11: 1 | D11: Does each user have a unique ID? | E11: =IF(D12="NA","No",IF(F12="Yes","No","Yes")) -> Yes | G11: =IF(OR(F11="No","NA"),"Recommended to have uniques ID for each user.","") -> #VALUE! | H11: Yes. Each user has a system-generated UUID as the internal primary identifier. The user ID used for login is also protected by a database uniqueness constraint, preventing duplicate accounts with the same ID. | J11: =IF(D12="NA","Y",IF(F11="Yes","Y","N")) -> N | K11: =IF(AND(OR(F11="No",F11="NA"),ISBLANK(H11)),"Please enter your comments","")
C12: 2 | D12: =IF(F4="Yes","NA","Others") -> Others | E12: =IF(D12="NA","No",IF(F11="Yes","No","Yes")) -> Yes | K12: =IF(AND(F12="Yes",ISBLANK(H12)),"Please enter your comments","")
A13: 4 | B13: Unique token for new session | C13: 1 | D13: On every successful Authentication event of the user or service, is a new session token generated and any old session associated with the same user or service invalidated? | E13: =IF(D14="NA","No",IF(F14="Yes","No","Yes")) -> Yes | G13: =IF(F13="Yes","On every successful Authentication event of the user or service, a fresh new session token generated and any old session associated with the same user or service invalidated.",IF(OR(F13="No",F13="NA"),"Recommend to generate a fresh new session token on every successful authetication and invalidate any old session associated with the same user or service.","")) | H13: Partially. A new cryptographically secure session token is generated after every successful login. However, earlier sessions for the same user are not automatically invalidated at login, so multiple concurrent sessions are currently permitted. | J13: =IF(D14="NA","Y",IF(F13="Yes","Y","N")) -> N | K13: =IF(AND(OR(F13="No",F13="NA"),ISBLANK(H13)),"Please enter your comments","")
C14: 2 | D14: =IF(F4="Yes","NA","Others") -> Others | E14: =IF(D14="NA","No",IF(F13="Yes","No","Yes")) -> Yes | K14: =IF(AND(F14="Yes",ISBLANK(H14)),"Please enter your comments","")
A15: 5 | B15: Logout | C15: 1 | D15: Does the application inform the user on logging out and seek confirmation to logout the user on clicking Logout button? | E15: =IF(D16="NA","No",IF(F16="Yes","No","Yes")) -> Yes | G15: =IF(OR(F15="No","NA"),"Recommend to inform the user on logging out when logout button is clicked.","") -> #VALUE! | H15: no | J15: =IF(D16="NA","Y",IF(F15<>"Yes","N",J17)) -> N | K15: =IF(AND(OR(F15="No",F15="NA"),ISBLANK(H15)),"Please enter your comments","")
C16: 2 | D16: =IF(F4="Yes","NA","Others") -> Others | E16: =IF(D16="NA","No",IF($F15<>"Yes","Yes","No")) -> Yes | H16: Logout invalidates the active server-side session, deletes the browser’s session cookie, clears the authenticated user state, and prevents further use of that token. A confirmation dialog may be added if required by the organization’s user-experience or security policy. | K16: =IF(AND(F16="Yes",ISBLANK(H16)),"Please enter your comments","")
C17: 1.1 | D17: Is the session token invalidated on logout? | E17: =IF($F15="Yes","Yes","No") -> No | G17: =IF(F17="Yes","Application informs the user on logging out when logout button is clicked. Session is invalidated on logout.",IF(OR(F17="No",F17="NA"),"Application informs the user on logging out when logout button is clicked. Recommend to invalidate the session token on logout.","")) | H17: Implemented. On logout, the server-side session record is deleted from the database and the session cookie is removed, preventing reuse of the token. | J17: =IF(F17="Yes","Y","N") -> N | K17: =IF(AND(OR(F17="No",F17="NA"),ISBLANK(H17)),"Please enter your comments","")
A18: 6 | B18: Password management event logging | C18: 1 | D18: Does every password change/reset event generate an audit trail that contains parameters such as Date & Time, User ID & Success or Failure status? | E18: =IF(D19="NA","No",IF(F19="Yes","No","Yes")) -> Yes | G18: =IF(F18="Yes","Every Password Change/Reset event generate an audit trail which contains parameters like User's IP Address, Date & Time, User ID & Success or Failure status.",IF(OR(F18="No",F18="NA"),"Recommend to generate an audit trail on every password change/reset event containing parameters like User's IP Address, Date & Time, User ID & Success or Failure status.","")) | H18: no | J18: =IF(D19="NA","Y",IF(F18="Yes","Y","N")) -> N | K18: =IF(AND(OR(F18="No",F18="NA"),ISBLANK(H18)),"Please enter your comments","")
C19: 2 | D19: =IF(F4="Yes","NA","Others") -> Others | E19: =IF(D19="NA","No",IF(F18="Yes","No","Yes")) -> Yes | K19: =IF(AND(F19="Yes",ISBLANK(H19)),"Please enter your comments","")
A20: 7 | B20: Encrypted communication for secrets in transit | C20: 1 | D20: Is the authentication token or secret protected by using encryption and secure communication channels like HTTPS? | E20: =IF(D21="NA","No",IF(F21="Yes","No","Yes")) -> Yes | G20: =IF(F20="Yes","Authentication token or secret protected by using encryption and secure communication channels like HTTPS.",IF(OR(F20="No",F20="NA"),"Recommend to protect authentication token or secret by using encryption and secure communication channels like HTTPS.","")) | H20: Partially. Session tokens use secure cookies in production, but HTTPS/TLS must be enforced by the production infrastructure. | J20: =IF(D21="NA","Y",IF(F20="Yes","Y","N")) -> N | K20: =IF(AND(OR(F20="No",F20="NA"),ISBLANK(H20)),"Please enter your comments","")
C21: 2 | D21: =IF(F4="Yes","NA","Others") -> Others | E21: =IF(D21="NA","No",IF(F20="Yes","No","Yes")) -> Yes | K21: =IF(AND(F21="Yes",ISBLANK(H21)),"Please enter your comments","")
A22: 8 | B22: Secure password recovery | C22: 1 | D22: Is the user prompted to enter Security/Secret question and answer? | E22: =IF(D25="NA","No",IF(OR(F23="Yes",F25="Yes",F24="Yes"),"No","Yes")) -> Yes | H22: no | J22: =IF(D25="NA","Y",IF(AND('Asset Info'!B9="Intranet",F22="Yes"),"Y",J26)) -> N
C23: 2 | D23: Is the password reset link shared with users through mail to set their own password? | E23: =IF(D25="NA","No",IF(OR(F25="Yes",F22="Yes",F24="Yes"),"No","Yes")) -> Yes | G23: =IF(F23="Yes","Forgot password option is available. An email is send to the user with a password reset link to set the password.","") | H23: no | J23: =IF(F23="Yes","Y","N") -> N
C24: 3 | D24: Does admin reset the password? | E24: =IF(D25="NA","No",IF(OR(F22="Yes",F23="Yes",F25="Yes"),"No","Yes")) -> Yes | H24: no
C25: 4 | D25: =IF(F4="Yes","NA","Others") -> Others | E25: =IF(D25="NA","No",IF(COUNTIF(F22:F24,"Yes")>0,"No","Yes")) -> Yes | K25: =IF(AND(F25="Yes",ISBLANK(H25)),"Please enter your comments","")
C26: 1.1 | D26: Is OTP validation implemented? | E26: =IF(AND('Asset Info'!B9="Internet",F22="Yes"),"Yes","No") -> No | G26: =IF(F26="Yes","Secure Password Recovery mechanism is implemented by using multi-factor authentication elements ( for example ask security question something they know, and then send a generated token to a device/email - something they own).",IF(OR(F26="No",F26="NA"),"Recommend to have second factor of authentication like OTP for securely recovering the password.","")) | H26: no | J26: =IF(F26="Yes","Y","N") -> N | K26: =IF(AND(OR(F26="No",F26="NA"),ISBLANK(H26)),"Please enter your comments","")
C27: 3.1 | D27: Is the admin shared password forced to change on first login? | E27: =IF(F24="Yes","Yes","No") -> No | G27: =IF(ISBLANK(F27),"",IF(F27="Yes","Admin resets the password and it is forced to change on first login by the user","Recommended to force the users to change their password upon their next login after a password reset by admin")) | H27: no | J27: =IF(F27="Yes","Y","N") -> N
A28: 9 | B28: Latest version of TLS used for communication | C28: 1 | D28: Is TLSv1.2 or above used for secure communication? | E28: =IF(F29="Yes","No","Yes") -> Yes | G28: =IF(F28="Yes","TLSv1.2 or above is used for secure communication.",IF(OR(F28="No",F28="NA"),"TLSv1.2 or above is recommended to use for secure communication","")) | J28: =IF(F28="Yes","Y","N") -> N | K28: =IF(AND(OR(F28="No",F28="NA"),ISBLANK(H28)),"Please enter your comments","")
C29: 2 | D29: Others | E29: =IF(F28="Yes","No","Yes") -> Yes | K29: =IF(AND(F29="Yes",ISBLANK(H29)),"Please enter your comments","")
A30: 10 | B30: Anti-automation controls | C30: 1 | D30: =IF(F4="Yes","NA",IF('Asset Info'!B9="Internet","Is CAPTCHA enforced on publicly available pages like Login page or any page that does not require authentication?","As it is a Intranet application anti-automation controls like CAPTCHA is not mandatory.")) -> As it is a Intranet application anti-automation controls like CAPTCHA is not mandatory. | E30: =IF('Asset Info'!B9="Internet","Yes","No") -> No | G30: =IF(F30="No","Recommend to enforce CAPTCHA on publicly available pages like Login page or any page that does not require authentication","") | H30: no | J30: =IF(OR(D30="NA",'Asset Info'!B9="Intranet"),"Y",IF(F30<>"Yes","N",IF(COUNTIF(J31:J32,"Y")>0,"Y","N"))) -> N
C31: 1.1 | D31: Are third-party or standard CAPTCHA libraries used? | E31: =IF(AND(F30="Yes",F32<>"Yes"),"Yes","No") -> No | G31: =IF(F31="Yes","Application uses CAPTCHA as anti-automation control. Standard CAPTCHA libraries used for generation.","") | H31: no | J31: =IF(F31="Yes","Y","N") -> N
C32: 1.2 | D32: Is custom code used for CAPTCHA? | E32: =IF(AND(F30="Yes",F31<>"Yes"),"Yes","No") -> No | H32: no | J32: =J33 -> N
C33: 1.2.1 | D33: Is CAPTCHA generation logic available on the server side? | E33: =IF(F32="Yes","Yes","No") -> No | G33: =IF(F33="Yes","Application uses CAPTCHA as anti-automation control. Custom CAPTCHA generation done on the server side.",IF(OR(F33="No",F33="NA"),"Application uses CAPTCHA as anti-automation control. Custom CAPTCHA generation used. Recommended to generate and validate CAPTCHA on the server side.","")) | H33: no | J33: =IF(F33="Yes","Y","N") -> N
A34: 11 | B34: Multifactor authentication for sensitive transactions | C34: 1 | D34: Does the application involve sensitive transactions (like changing the shipping address for a purchase, or delegation of duties etc)? | E34: =IF(D35="NA","No",IF(F35="Yes","No","Yes")) -> Yes | G34: =IF(OR(F34="No",F34="NA"),"Application does not have any sensitive transaction","") | H34: no | J34: =IF(D35="NA","Y",IF(F34="Yes",J36,IF(NOT(ISBLANK(F34)),"Y","N"))) -> N
C35: 2 | D35: =IF(F4="Yes","NA","Others") -> Others | E35: =IF(D35="NA","No",IF(ISBLANK($F34),"Yes","No")) -> Yes | K35: =IF(AND(F35="Yes",ISBLANK(H35)),"Please enter your comments","")
C36: 1.1 | D36: Is the user re-authenticated or verified through Profile Passwords or OTP mechanism? | E36: =IF($F34="Yes","Yes","No") -> No | G36: =IF(F36="Yes","For sensitive transactions, application re-authenticates the user or verify through Profile Passwords or OTP mechanism.",IF(OR(F36="No",F36="NA"),"For sensitive transactions, recommend to re-authenticates the user or verify through Profile Passwords or OTP mechanism.","")) | H36: no | J36: =IF(F36="Yes","Y","N") -> N | K36: =IF(AND(OR(F36="No",F36="NA"),ISBLANK(H36)),"Please enter your comments","")
A37: 12 | B37: IP based restriction for critical functionality | C37: 1 | D37: Does the application have critical functionalities like admin setting certain role entitlements or payment configuration etc? | E37: =IF('Asset Info'!B10="No","No",IF(F4="Yes","No",IF(D37<>"NA","Yes","No"))) -> Yes | G37: =IF(OR(F37="No",F37="NA"),"Application do not have any critical functionality","") | H37: no | J37: =IF(E37="No","Y",IF(F4="Yes","Y",IF(F37="Yes",J38,IF(NOT(ISBLANK(F37)),"Y","N")))) -> N
C38: 1.1 | D38: Is IP based restriction enabled for accessing such functionality? | E38: =IF(F37="Yes","Yes","No") -> No | G38: =IF(F38="Yes","Application has critical functionality and Ipbased restrcition enabled for accessing such pages/functionality.",IF(OR(F38="No",F38="NA"),"Application has critical functionality. Recommend to have IP based access to those pages or functionality.","")) | H38: no | J38: =IF(F38="Yes","Y","N") -> N | K38: =IF(AND(OR(F38="No",F38="NA"),ISBLANK(H38)),"Please enter your comments","")
A39: Audit trails and logging
A40: 1 | B40: Clock synchronization for all devices and servers. | C40: 1 | D40: Does the application have the time synchronised with NTP, other applications and systems? | E40: Yes | G40: =IF(F40="Yes","The application has the time synchronised with NTP, other applications and systems.",IF(OR(F40="No",F40="NA"),"Recommended to have the time synchronised with NTP, other applications and systems.","")) | H40: no | J40: =IF(F40="Yes","Y","N") -> N | K40: =IF(AND(OR(F40="No",F40="NA"),ISBLANK(H40)),"Please enter your comments","")
...

Sheet Gen AI Audit Sheet
A1: TCS Confidential
A3: Application ID (As per ARM)
A4: Application Name
A5: Risk Category (Low / Medium / High / Very High)
A7: Sr.No | B7: Section | C7: Section Name | D7: Sub | E7: Requirement | F7: Application team Remarks | G7: Reviewer's Comments | H7: Benchmark ReferenceGuidelines
A8: 1 | B8: V1 | C8: Secure Configuration | D8: 1.1 | E8: Identify any components that store secrets, like API keys, for third-party systems, like hosted LLMs and vector databases, and ensure the secure handling of these credentials according to section V2.10 “Service Authentication” of the OWASP ASVS. | F8: The application uses Mistral API and PostgreSQL, currently supplied through environment variables (.env files are Git-ignored) | H8: 1.Have you utilized Azure Key Vault to store API keys and secret keys? 2.Have you ensured that a private connection is enabled?
A9: 2 | B9: V1 | C9: Secure Configuration | D9: 1.2 | E9: For self-hosted LLMs, ensure they are appropriately segregated within the network to prevent direct exposure to end-users unless such access is required. | F9: no | H9: Are Self Hosted LLM's utilized?
A10: 3 | B10: V1 | C10: Secure Configuration | D10: 1.3 | E10: Maintain an up-to-date inventory of all LLM instances and apply regular updates and patches to self-hosted models. | F10: no | H10: Are Self Hosted LLM's utilized?
A11: 4 | B11: V1 | C11: Secure Configuration | D11: 1.4 | E11: Perform and document regular configuration reviews for configuration settings associated with the LLM-powered system. | F11: Content filtering uses mistral-moderation-latest for custom instructions and output templates; flagged content is blocked and results are logged for review. Service endpoints for PostgreSQL, MCP are environment-configured, while CORS is currently limited to local development origins. A formal periodic configuration-review process and fail-closed moderation behavior must be established before production certification. | H11: How are these points being managed needs to be addressed 1. Content Filter Configuration 2. Endpoint Configuration
A12: 5 | B12: V2 | C12: Model Lifecycle | D12: 2.1 | E12: Ensure that the lifecycle of machine learning models is integrated into the existing Secure Software Development Lifecycle (SSDLC). Defined processes should exist and be available for each stage of the lifecycle of ML models. | F12: no | H12: Application team to confirm whether there is requirement to use new model/train model else this case will not be applicable
A13: 6 | B13: V2 | C13: Model Lifecycle | D13: 2.2 | E13: Document user stories defining the requirements and use cases for any new ML model being produced. | F13: no | H13: Application team will share the user story as per their usecase
A14: 7 | B14: V2 | C14: Model Lifecycle | D14: 2.3 | E14: Ensure that model training resources and datasets are acquired from trustworthy sources and validated for correctness or free from malicious data. | F14: Applicable to RAG data. Only authenticated deal owners can upload files, text, or URLs to deal-specific Mistral Document Libraries. Company data is owner-scoped, section URLs are validated, and retrieved source details and citations are recorded for verification. Duplicate legacy uploads are identified using SHA-256 hashes. | H14: Data used by UseCase/RAG (Retrival Augmented Generated / Grounded) needs to be verified [Applicable for Upload functionality in Gen AI UseCase]
A15: 8 | B15: V2 | C15: Model Lifecycle | D15: 2.4 | E15: Ensure that model training resources and datasets are properly secured from unauthorized modification once acquired. | F15: Uploaded RAG files are protected through session-based authentication, role-based access, and deal-level authorization. File metadata—including deal ID, filename, source type, size, Mistral file ID, and creation time—is stored, while uploads are recorded in application logs/traces. Files cannot be edited in place; changes require authorized deletion and re-upload. | H15: Have you confirmed whether there are mechanisms in place to monitor and log any access or modifications made to the training resources and datasets/ or whether activities related to files uploaded by users are being logged? This helps in detecting any unauthorized attempts to alter the data and provides a record for auditing purposes. Recommendation: Application has to maintain the authorization properly to avoid improper modification of data [Applicable for Upload functionality in Gen AI UseCase]
A16: 9 | B16: V2 | C16: Model Lifecycle | D16: 2.5 | E16: Ensure that the source of any training resources and datasets is documented. | F16: Applicable to RAG inputs. The application records company-library documents, deal-specific file/URL/text uploads, PostgreSQL source tables, and section URLs. Stored metadata includes source type, filename or URL, deal association, file/library ID, size, timestamp, and retrieved-source/citation details. | H16: For now, Application team has to maintain record of the datasets that is shared to LLM [Applicable for Upload functionality in Gen AI UseCase]
A17: 10 | B17: V2 | C17: Model Lifecycle | D17: 2.6 | E17: Ensure that any data cleaning or other modifications to the original training resources are tracked and auditable to reduce the risk of data poisoning from an insider threat. | F17: Uploaded files are treated only as RAG data and are not executed by the application. SHA-256 hashes, source metadata, extraction method, page count, and extracted content are recorded; OCR/upload operations are logged. User-provided instructions and templates are moderated, with flagged content blocked before generation. | H17: Application team to share information on below points 1. Application has to maintain checks to block harmful content from getting executed 2. Everything should get added in logs. [Applicable for Upload functionality in Gen AI UseCase]
A18: 11 | B18: V2 | C18: Model Lifecycle | D18: 2.7 | E18: Ensure that the intellectual property rights of model training resources and datasets are checked to avoid potential license or copyright infringement issues. Ensure this process is documented and auditable. | F18: no | H18: Application team to share information on below points 1. Data Ownership Mail 2. Plagarism Check (IRC) 3. All features in the AI Services should be first approved from Legal end.
A19: 12 | B19: V2 | C19: Model Lifecycle | D19: 2.8 | E19: Ensure that model training resources are audited for sensitive data (such as PII, internal company data, etc.) and cleaned before training to mitigate sensitive data exposure in model responses. | F19: no | H19: Privacy Approval to be shared by application team (for data sent to LLM as part of RAG/Context) for sensitive information [Applicable for Upload functionality in Gen AI UseCase]
... A93: 83 | B93: C6 | C93: Custom: Data Protection & Sanitization | D93: 6.11 | E93: Validate Data Encryption during transit and at rest for all sensitive communications and stored data | F93: Mistral communication uses HTTPS, and passwords/session tokens are protected using hashing. | H93: Whether you have examined network traffic to confirm the use of TLS for data in transit and inspected storage mechanisms to ensure encryption is applied to sensitive data?

Sheet Report
A1: Asset Registration ID | B1: ='Asset Info'!B1 -> Tipar-ID
A2: Tool Evaluation Status | B2: =IF('Asset Info'!B11="No",IF(COUNTIF(C11:C137,"Not Approved")>0,"Not Cleared","Cleared"),"Not Cleared") -> Not Cleared
A3: Reviewer Evaluation Status
A4: Reviewer Final Comments
A6: Total Applicable Checklist Items | B6: =SUM(B7:B8) -> 127
A7: Total Autoapproved | B7: =COUNTIF(C11:C137,"Approved") -> 14
A8: Total Not Autoapproved | B8: =COUNTIF(C11:C137,"Not Approved") -> 113
A10: Security Foundation Parameter | B10: Checklist category | C10: Approval Status
A11: Authentication and Password Management | B11: Strong password policy | C11: =IF(COUNTIF(Checklist!J3:Checklist!J5,"Y")>0,"Approved","Not Approved") -> Not Approved
B12: Secure storage of credentials / keys | C12: =IF(Checklist!J9="Y","Approved","Not Approved") -> Not Approved
B13: Unique Id for each user | C13: =IF(Checklist!J11="Y","Approved","Not Approved") -> Not Approved
B14: Unique token for new session | C14: =IF(Checklist!J13="Y","Approved","Not Approved") -> Not Approved
B15: Logout | C15: =IF(Checklist!J15="Y","Approved","Not Approved") -> Not Approved
B16: Password management event logging | C16: =IF(Checklist!J18="Y","Approved","Not Approved") -> Not Approved
B17: Encrypted communication for secrets in transit | C17: =IF(Checklist!J20="Y","Approved","Not Approved") -> Not Approved
B18: Secure password recovery | C18: =IF(COUNTIF(Checklist!J22:Checklist!J27,"Y")>0,"Approved","Not Approved") -> Not Approved
B19: Latest version of TLS used for communication | C19: =IF(Checklist!J28="Y","Approved","Not Approved") -> Not Approved
B20: Anti-automation controls | C20: =IF(Checklist!J30="Y","Approved","Not Approved") -> Not Approved
B21: Multi-factor authentication for sensitive transactions | C21: =IF(Checklist!J34="Y","Approved","Not Approved") -> Not Approved
B22: IP based restriction for critical functionality | C22: =IF(Checklist!J37="Y","Approved","Not Approved") -> Not Approved
A23: Audit-trails and Logging | B23: Clock synchronization for all devices and servers | C23: =IF(Checklist!J40="Y","Approved","Not Approved") -> Not Approved
B24: Capture at least source IP address, timestamp, action owner Id, event Id and resource Id | C24: =IF(Checklist!J41="Y","Approved","Not Approved") -> Not Approved
B25: Differentiate events from errors | C25: =IF(Checklist!J42="Y","Approved","Not Approved") -> Not Approved
B26: Append only mode for trails and logs | C26: =IF(Checklist!J43="Y","Approved","Not Approved") -> Not Approved
B27: Use the standard APIs or libraries for logging (such as Log4j, Log4Net) | C27: =IF(Checklist!J44="Y","Approved","Not Approved") -> Not Approved
B28: Maintain audit-trail for administrative actions separately | C28: =IF(Checklist!J46="Y","Approved","Not Approved") -> Not Approved
B29: Log sensitive information in encrypted format. | C29: =IF(Checklist!J47="Y","Approved","Not Approved") -> Not Approved
B30: Plan sufficient disk space for logs. | C30: =IF(Checklist!J49="Y","Approved","Not Approved") -> Not Approved
B31: Appropriately select logging strategy based on date, user or events. | C31: =IF(COUNTIF(Checklist!J50:Checklist!J52,"Y")>0,"Approved","Not Approved") -> Not Approved
B32: Periodically analyze logs for anomaly or misbehavior | C32: =IF(Checklist!J54="Y","Approved","Not Approved") -> Not Approved
B33: Have restricted access for logs. | C33: =IF(Checklist!J56="Y","Approved","Not Approved") -> Not Approved
B34: Encrypt admin audit-trail and protect it from admin. | C34: =IF(Checklist!J57="Y","Approved","Not Approved") -> Not Approved
A35: Access Control | B35: Validate each request for authorization | C35: =IF(Checklist!J59="Y","Approved","Not Approved") -> Not Approved
B36: Always rely on Server Side data for access control decisions | C36: =IF(Checklist!J60="Y","Approved","Not Approved") -> Not Approved
B37: Offer minimal functionality to anonymous users | C37: =IF(Checklist!J61="Y","Approved","Not Approved") -> Not Approved
B38: Create centralized access control system through ACL | C38: =IF(Checklist!J63="Y","Approved","Not Approved") -> Not Approved
B39: Provide no privileges to an account when it is first created | C39: =IF(Checklist!J65="Y","Approved","Not Approved") -> Not Approved
B40: Classify data to perform Encryption, Hashing, Encoding or Masking | C40: =IF(Checklist!J66="Y","Approved","Not Approved") -> Not Approved
B41: Restrict a normal user's access to system resources | C41: =IF(Checklist!J67="Y","Approved","Not Approved") -> Not Approved
B42: Maintain Audit Trails for sensitive Transactions | C42: =IF(Checklist!J68="Y","Approved","Not Approved") -> Approved
...
