Workbook

Sheet Read me
A1: Document History
A2: Name of the Artifact | B2: TCS Security QOPD Template
A3: Version | B3: 4.0
A4: Release Date | B4: 45504
A6: Revision History
A7: Date | B7: Release No. | C7: Remarks
A8: 41164 | B8: 1.0 | C8: Formal Release of the document
A9: 41362 | B9: 1.1 | C9: Examples added to the given security quality characteristics
A10: 45075 | B10: 2.0 | C10: Objective based questions for the security quality characteristics.
A11: 45126 | B11: 3.0 | C11: Modified question for password policy based on Internet and intranet criteria. Updated Bypass authentication and Sensitive Data Disclosure line items.
A12: 45181 | B12: 3.1 | C12: 1. Auto-approval for Authentication related quetsions when 'No user management module' option against 'User Registartion' is selected. 2. Updated the question for 'Access Control to code - Program source code'
A13: 45504 | B13: 4.0 | C13: Simplification of questions based on application and deployment type.
A15: © Copyright [2023], Tata Consultancy Services Limited. All Rights Reserved. Document ID CGKD009334 Unauthorized access, copying, replication, distribution, transmission, modification, adaptation or translation or use without express written permission is prohibited.
A18: Usage Guidelines
A19: • Asset details to be filled by the asset team in the Asset Info sheet. Answer the questions related to the asset in the Contextual Questions table. • Checklist sheet consists of all the line items that need to be addressed and the report sheet comprises the overall review report including the approval status. •The Applicability column in the Checklist sheet shows whether that particular line item is applicable or not; if it is 'Yes', then the asset team needs to select an appropriate Option (column F) from the drop down and if it is 'No' or if a row is grayed out it is not applicable and thus, need not be answered. •If the asset team selects the Option 'Yes' for any line item where Security Checkpoints is 'Others' or selects the Option 'No' for any line item that recommends something, they have to enter their comments mandatorily in the respective column; else the comments are optional. •Against any line item: - If the asset team wants to reset the value in the Options column, they can simply delete the content in the options column. - Auto Approval column indicates whether that particular line item is eligible for auto approval or not. Y-indicates the line item is auto-approved, N not auto-approved and NA the line item is Not Applicable - Application teams comments are mandatory for not auto-approved line items. •Reviewer should update 'Reviewer Evaluation Status' and 'Reviewer Final Comments' when by default the QOPD is not auto-approved.

Sheet Asset Info
A2: Asset TIPAR ID
A3: Asset Information
A4: Asset Name & version
A5: Application Category
A6: Application Deployment Environment Owned BY
A8: Contextual Questions
A9: Internet/Intranet facing
A10: Does the application deal with business sensitive data like financial information like payment processing, business finance data storage?
A11: Does the application deal with Personal sensitive information like Aadhar/SSN PII/PHI or Personal sensitive financial information like credit card details?

Sheet Checklist
E1: =IF(OR(COUNTBLANK('Asset Info'!B2:B6)>0,COUNTBLANK('Asset Info'!B9:B11)>0),"Please fill asset information and contextual questions in Asset Info sheet","") -> Please fill asset information and contextual questions in Asset Info sheet
A3: Authentication
A4: NFR | B4: Category | C4: Radio Options | D4: Security Checkpoints | E4: Applicability | F4: Option | G4: Remarks | H4: Application Team comments | I4: Reviewer Comments | J4: Auto Approval
A5: 1 | B5: User registration | C5: 1 | D5: Does the application provide the option of self-registration to the users? | E5: =IF(OR(OR('Asset Info'!B5="Desktop",'Asset Info'!B5="Code based library"),'Asset Info'!B5="APIs Only"),"No",IF(COUNTIF(F6:F9,"Yes")>0,"No","Yes")) -> Yes | G5: =IF(F5="Yes","Users register themselves into the application by following the password policy.","") | J5: =IF(F5<>"Yes","N","Y") -> N
C6: 2 | D6: Does the admin registers the user? | E6: =IF(OR(OR('Asset Info'!B5="Desktop",'Asset Info'!B5="Code based library"),'Asset Info'!B5="APIs Only"),"No",IF(OR(F5="Yes",COUNTIF(F7:F9,"Yes")>0),"No","Yes")) -> Yes | J6: =IF(AND(OR(F6="Yes",F8="Yes"),COUNTIF(J14:J15,"Y")>0),"Y","N") -> N
C7: 3 | D7: =IF('Asset Info'!B5="Desktop","Is it a Desktop application without user authentication?",IF('Asset Info'!B5="APIs Only","Is it a API-Based application without authentication?",IF('Asset Info'!B5="Code based library","NA","Does the application has no user registration module as it connects to customer SSO/LDAP/IDM?"))) -> Does the application has no user registration module as it connects to customer SSO/LDAP/IDM? | E7: =IF(OR(COUNTIF(F5:F6,"Yes")>0,COUNTIF(F8:F9,"Yes")>0),"No","Yes") -> Yes | G7: =IF(AND('Asset Info'!B5="Desktop",Checklist!F7="Yes"),"Application has no user registration module and is available as Desktop Application without user authentication",IF('Asset Info'!B5="Code based library","Application is a code based library and do not have any user registration module",IF(AND('Asset Info'!B5="APIs Only",Checklist!F7="Yes"),"",IF(F7="Yes","Application do not have user registration module and connect to customer LDAP/IDM/SSO to identify and authenticate the user.","")))) | J7: =IF('Asset Info'!B5="Code based library","Y",IF(AND('Asset Info'!B5="Desktop",Checklist!F7="Yes"),"Y",IF('Asset Info'!B5="APIs Only","N",IF(F7="Yes","Y","N")))) -> N
C8: 4 | D8: Does the application provide the option of self-registration to the users along with the possibility for admin to register the users? | E8: =IF(OR(OR('Asset Info'!B5="Desktop",'Asset Info'!B5="Code based library"),'Asset Info'!B5="APIs Only"),"No",IF(OR(COUNTIF(F5:F7,"Yes")>0,COUNTIF(F9,"Yes")>0),"No","Yes")) -> Yes | J8: =IF(AND(J6="Y",F8="Yes"),"Y","N") -> N
C9: 5 | D9: Others | E9: =IF(OR(OR('Asset Info'!B5="Desktop",'Asset Info'!B5="Code based library"),'Asset Info'!B5="APIs Only"),"No",IF(COUNTIF(F5:F8,"Yes")>0,"No","Yes")) -> Yes | J9: N | K9: =IF(AND($F9="Yes",ISBLANK($H9)),"Please enter your comments","")
C10: =IF(F8="Yes","4.1","2.1") -> 2.1 | D10: Is a random password generated and shared with the user through auto-mailer option when admin registers the user? | E10: =IF(OR(COUNTIF(F11:F14,"Yes")>0,AND(F6<>"Yes",F8<>"Yes")),"No","Yes") -> No
C11: =IF(F8="Yes","4.2","2.2") -> 2.2 | D11: Is a default password shared with the user with limited activation time when admin registers the user? | E11: =IF(OR(OR(COUNTIF(F10,"Yes")>0,COUNTIF(F12:F14,"Yes")>0),AND(F6<>"Yes",F8<>"Yes")),"No","Yes") -> No
C12: =IF(F8="Yes","4.3","2.3") -> 2.3 | D12: Is it a random/default password shared with user by admin when admin registers the user? | E12: =IF(OR(OR(COUNTIF(F10:F11,"Yes")>0,COUNTIF(F13:F14,"Yes")>0),AND(F6<>"Yes",F8<>"Yes")),"No","Yes") -> No
C13: =IF(F8="Yes","4.4","2.4") -> 2.4 | D13: Is an activation link shared with the users to set their own password when admin registers the user? | E13: =IF(OR(OR(COUNTIF(F10:F12,"Yes")>0,COUNTIF(F14,"Yes")>0),AND(F6<>"Yes",F8<>"Yes")),"No","Yes") -> No | G13: =IF(F13="Yes","User is registered by Admin. Activation link is shared with the user to set the password following the defined password policy.","") | J13: =IF($F13<>"Yes","N","Y") -> N
C14: =IF(F8="Yes","4.5","2.5") -> 2.5 | D14: Others | E14: =IF(OR(COUNTIF(F10:F13,"Yes")>0,AND(F6<>"Yes",F8<>"Yes")),"No","Yes") -> No | S14: User registers themselves into the application by following the defined password policy and has a functionality where the admin also registers the user Random password is generated and shared with user through auto mail Recommend to force the user to change the password on first login. | T14: User registers himself/herself into the application by following the defined password policy, and has a functionality where the admin also registers the user. Default password is shared with user with limited activation time.Recommend to mandate the user to change the password on first login.
C15: =IF(AND(F6="Yes",F12="Yes"),"2.3.1",IF(AND(F6="Yes",F10="Yes"),"2.1.1",IF(AND(F6="Yes",F11="Yes"),"2.2.1",IF(AND(F8="Yes",F12="Yes"),"4.3.1",IF(AND(F8="Yes",F10="Yes"),"4.1.1",IF(AND(F8="Yes",F11="Yes"),"4.2.1","2.1.1")))))) -> 2.1.1 | D15: Is it mandatory for the users to change their password after the first login? | E15: =IF(AND(OR(F6="Yes",F8="Yes"),COUNTIF(F10:F12,"Yes")>0),"Yes","No") -> No | G15: =IF(AND(ISBLANK(F8),ISBLANK(F6)),"",IF(AND(F8="Yes",OR(F15="No",F15="NA")),S14, IF(AND(F8="Yes",F15="Yes"),S15,IF(OR(F15="No",F15="NA"),#REF!,IF(ISBLANK(F15),"",S16))))) | J15: =IF($F15<>"Yes","N","Y") -> N | S15: User registers himself/herself into the application by following the defined password policy,and has a functionality where the admin also registers the user. Where random password is generated and shared with user through auto-mailer and the user is forced to change the password on first login. | T15: User registers himself/herself into the application by following the defined password policy, and has a functionality where the admin also registers the user. Default password is shared with user with limited activation time and the user is mandated to change the password on first login.
C16: 3.1 | D16: =IF('Asset Info'!B5="APIs Only","Is the application just used as a middle layer without API keys or authentication tokens?","Does the application provide the option of self-registration to the users?") -> Does the application provide the option of self-registration to the users? | E16: =IF(OR(F17="Yes",F18="Yes"),"No",IF(AND('Asset Info'!B5="APIs Only",F7="Yes"),"Yes",IF(AND('Asset Info'!B5="APIs Only",F7="No"),"No",IF(AND('Asset Info'!B5="Desktop",Checklist!F7="No"),"Yes","No")))) -> No | G16: =IF(AND('Asset Info'!B5="API",F16="Yes"),"API based application used as a middle layer without API keys or authentication tokens.",IF(AND('Asset Info'!B5="API",F16="No"),"",IF(F16="Yes","Application is a desktop application and allows user for self registration by following password policy",""))) | J16: =IF(AND('Asset Info'!B5="APIs Only",F16="Yes"),"Y",IF(AND('Asset Info'!B5="APIs Only",F16="No"),"N",IF(AND(E16="Yes",$F16="Yes"),"Y","N"))) -> N | S16: User is registered by Admin. Random password is generated and shared with user through auto-mailer and the user is forced to change the password on first login. | T16: User is registered by Admin. Default password is shared with user with limited activation time and the user is mandated to change the password on first login.
C17: 3.2 | D17: =IF('Asset Info'!B5="APIs Only","Is the application having API keys or authentication tokens for authenticating users or applications?","Does the admin registers the user?") -> Does the admin registers the user? | E17: =IF(OR(F16="Yes",F18="Yes"),"No",IF(OR(AND('Asset Info'!B5="Desktop",Checklist!F7="No"),AND('Asset Info'!B5="APIs Only",F7="No")),"Yes","No")) -> No | G17: =IF(AND('Asset Info'!B5="APIs Only",F17="Yes"),"API based application using API keys or authentication tokens for authenticating users or applications",IF(F17="Yes","Application is a desktop application and admin registers the user","")) | J17: =IF(AND('Asset Info'!B5="API",AND(F17="Yes",F7="No")),"Y","N") -> N
C18: 3.3 | D18: Others | E18: =IF(OR(F16="Yes",F17="Yes"),"No",IF(OR(AND('Asset Info'!B5="Desktop",Checklist!F7="No"),AND('Asset Info'!B5="APIs Only",F7="Yes")),"Yes","No")) -> No | J18: =IF(F18="Yes","N","") | K18: =IF(AND(AND($F18="Yes",ISBLANK($H18)),$F7="Yes"),"Please enter your comments","")
C19: 3.2.1 | D19: Is it mandatory for the users to change their password after the first login? | E19: =IF('Asset Info'!B5="API","No",IF(F17="Yes","Yes","No")) -> No | J19: =IF($F19<>"Yes","N","Y") -> N
C20: 3.2.2 | D20: Others | E20: =IF('Asset Info'!B5="API","No",IF(F19="Yes","No",IF(F17="Yes","Yes","No"))) -> No
A21: 2 | B21: User identification and authentication | C21: 1 | D21: Is the user identified and authenticated using the username and credentials stored in the system? | E21: =IF(OR(OR(AND('Asset Info'!B5="Desktop",F7="Yes"),'Asset Info'!B5="Code based library"),'Asset Info'!B5="APIs Only"),"No",IF(OR(F23="Yes",E22="Yes"),"No","Yes")) -> Yes | G21: =IF(F21="Yes","Application identifies and authenticates the user by using the username and credentials stored in the system","") | J21: =IF(F21="Yes","Y","N") -> N
C22: 2 | D22: NA | E22: =IF(OR(OR(AND('Asset Info'!B5="Desktop",F7="Yes"),'Asset Info'!B5="Code based library"),'Asset Info'!B5="APIs Only"),"No",IF(F7="Yes","Yes","No")) -> No | G22: =IF(AND('Asset Info'!B5="Desktop",F7="Yes"),"Application has no user registration module and is available as Desktop Application without user authentication.",IF('Asset Info'!B5="Code based library","Application is a code based library and do not have any user authentication",IF(AND('Asset Info'!B5="APIs Only",F17="Yes"),"API based application using API keys or authentication tokens for authenticating users or applications",IF(AND('Asset Info'!B5="APIs Only",F16="Yes"),"API based application used as a middle layer without API keys or authentication tokens",IF(AND('Asset Info'!B5="API",F20="Yes"),"API based application",IF(AND(F7="Yes",E22="Yes"),"Application does not have user registration module and connect to customer LDAP/IDM/SSO to identify and authenticate the user.","")))))) | J22: =IF(OR(OR(AND('Asset Info'!B5="Desktop",F7="Yes"),'Asset Info'!B5="Code based library"),'Asset Info'!B5="APIs Only"),"NA",IF(AND('Asset Info'!B5="Web/Mobile",F7="Yes"),"Y","N")) -> N
C23: 3 | D23: Others | E23: =IF(OR(OR(AND('Asset Info'!B5="Desktop",F7="Yes"),'Asset Info'!B5="Code based library"),'Asset Info'!B5="APIs Only"),"No",IF(OR(E22="Yes",F21="Yes"),"No","Yes")) -> Yes | J23: N | K23: =IF(AND($F23="Yes",ISBLANK($H23)),"Please enter your comments","")
A24: 3 | B24: User password management | C24: 1 | D24: Does the application allow the user to reset password incase user forgets the password? | E24: =IF(OR(OR(AND('Asset Info'!B5="Desktop",F7="Yes"),'Asset Info'!B5="Code based library"),'Asset Info'!B5="APIs Only"),"No",IF(OR(OR(F25="Yes",F27="Yes"),COUNTIF(E26:E26,"Yes")>0),"No","Yes")) -> Yes | J24: =IF(AND(F24="Yes",COUNTIF(J28:J30,"Y")>0),"Y","N") -> N
C25: 2 | D25: Does the application allow admin to reset the password incase user forgets the password? | E25: =IF(OR(OR(AND('Asset Info'!B5="Desktop",F7="Yes"),'Asset Info'!B5="Code based library"),'Asset Info'!B5="APIs Only"),"No",IF(OR(OR(F24="Yes",F27="Yes"),COUNTIF(E26:E26,"Yes")>0),"No","Yes")) -> Yes | J25: =IF(AND(F25="Yes",OR(J31="Y",J32="Y")),"Y","N") -> N
C26: 3 | D26: NA | E26: =IF(OR(OR(AND('Asset Info'!B5="Desktop",F7="Yes"),'Asset Info'!B5="Code based library"),'Asset Info'!B5="APIs Only"),"No",IF(F7="Yes","Yes","No")) -> No | G26: =IF(AND('Asset Info'!B5="Desktop",F7="Yes"),"Application has no user registration module and is available as Desktop Application without user authentication.",IF('Asset Info'!B5="Code based library","Application is a code based library and do not have any user authentication",IF(AND('Asset Info'!B5="APIs Only",F17="Yes"),"API based application using API keys or authentication tokens for authenticating users or applications",IF(AND('Asset Info'!B5="APIs Only",F16="Yes"),"API based application used as a middle layer without API keys or authentication tokens",IF(AND('Asset Info'!B5="API",F20="Yes"),"API based application",IF(AND(F7="Yes",E26="Yes"),"Application does not have user registration module and connect to customer LDAP/IDM/SSO to identify and authenticate the user.","")))))) | J26: =IF(OR(OR(AND('Asset Info'!B5="Desktop",F7="Yes"),'Asset Info'!B5="Code based library"),'Asset Info'!B5="APIs Only"),"NA",IF(AND('Asset Info'!B5="Web/Mobile",F7="Yes"),"Y","N")) -> N
C27: 4 | D27: Others | E27: =IF(OR(OR(AND('Asset Info'!B5="Desktop",F7="Yes"),'Asset Info'!B5="Code based library"),'Asset Info'!B5="APIs Only"),"No",IF(OR(OR(F24="Yes",F25="Yes"),COUNTIF(E26:E26,"Yes")>0),"No","Yes")) -> Yes | J27: N | K27: =IF(AND($F27="Yes",ISBLANK($H27)),"Please enter your comments","")
C28: 1.1 | D28: Is the user prompted to enter Security/Secret question and answer? | E28: =IF(F24<>"Yes","No","Yes") -> No | G28: =IF(AND(F28="Yes",'Asset Info'!B9<>"Internet"),"Forgot password option is available. User is prompted to enter Security/Secret question and answer to reset the password.","") | J28: =IF(ISBLANK(F24),"N",IF(AND('Asset Info'!B5="Desktop",F28="Yes"),"Y",IF(AND(F28="Yes",'Asset Info'!B9<>"Internet"),"Y","N"))) -> N
C29: 1.1.1 | D29: Is OTP validation implemented? | E29: =IF('Asset Info'!B5="Desktop","No",IF(AND('Asset Info'!B9="Internet",F28="Yes"),"Yes","No")) -> No | G29: =IF(F29="Yes","Application has forgot password feature. Accepts Security/Secret question and answer and OTP is also validated",IF(F29="No","Recommended to implement OTP validation for an Internet application.","")) | J29: =IF(F29="Yes","Y","N") -> N
C30: 1.1.2 | D30: Is a password reset link shared with users through mail to set their own password? | E30: =IF(F28="No","Yes","No") -> No | G30: =IF(F30="Yes","Forgot password option is available. An email is send to the user with a password reset link to set the password.",IF(F30="No","Recommend to either provide option for security/secret question and answer or share password rest link to allow user resetting their forward","")) | J30: =IF(F30="Yes","Y","N") -> N
C31: 2.1 | D31: =IF('Asset Info'!B5="Desktop","Is random/default password shared with the user by admin?","Is a random password generated and shared with the user through auto-mailer option?") -> Is a random password generated and shared with the user through auto-mailer option? | E31: =IF(OR(COUNTIF(F32:F33,"Yes")>0,F25<>"Yes"),"No","Yes") -> No | J31: =IF($J34="N","N","Y") -> N
C32: 2.2 | D32: Is a default password shared with the user with limited activation time? | E32: =IF('Asset Info'!B5="Desktop","No",IF(OR(OR(F33="Yes",F31="Yes"),F25<>"Yes"),"No","Yes")) -> No | J32: =IF($J35="N","N","Y") -> N
C33: 2.3 | D33: Others | E33: =IF(OR(F25<>"Yes",COUNTIF(F31:F32,"Yes")>0),"No","Yes") -> No | K33: =IF(AND($F33="Yes",ISBLANK($H33)),"Please enter your comments","")
C34: 2.1.1 | D34: Is it mandatory to change the password after the first login? | E34: =IF(AND(F25="Yes",F31="Yes"),"Yes","No") -> No | G34: =IF(ISBLANK(F34),"",IF(F34="Yes",IF('Asset Info'!B5="Desktop","Admin has the option to reset the password. Random password is generated and shared with user by admin. User is forced to change the password on first login","Admin has the option to reset the password. Random password is generated and shared with user through auto-mailer and the user is forced to change the password on first login"),IF('Asset Info'!B5="Desktop","Admin has the option to reset the password. Random password is generated and shared with user by admin. Recommend to force the user to change the password on first login","Admin has the option to reset the password. Random password is generated and shared with user through auto-mailer. Recommend to force the user to change the password on first login"))) | J34: =IF($F34="Yes","Y","N") -> N
C35: 2.2.1 | D35: Is it mandatory to change the password after the first login? | E35: =IF(AND(F25="Yes",F32="Yes"),"Yes","No") -> No | G35: =IF(ISBLANK($F35),"",IF($F35="Yes","Admin has the option to reset the password. Default password is shared with user with limited activation time and the user is forced to change the password on first login.","Admin has the option to reset the password. Default password is shared with user with limited activation time. Recommend to force the user to change the password on first login.")) | J35: =IF($F35="Yes","Y","N") -> N
A36: 4 | B36: Password policy | C36: 1 | D36: =IF('Asset Info'!B9="Internet",_xlfn.CONCAT("Does the password policy consist of the following? Min length 8 to 12 characters, Max Length 50 to 64 characters, Atleast 1 upper case letter, Atleast 1 lower case letter, Atleast 1 digit, Atleast 1 special character,"," Password expiry after 30 or 60 days, Last five passwords are not allowed to be used while resetting the password."),_xlfn.CONCAT("Does the password policy consist of the following? Min length 8 to 12 characters, Max Length 50 to 64 characters,", "Atleast 1 upper case letter, Atleast 1 lower case letter, Atleast 1 digit, Atleast 1 special character" )) -> Does the password policy consist of the following? Min length 8 to 12 characters, Max Length 50 to 64 characters,Atleast 1 upper case letter, Atleast 1 lower case letter, Atleast 1 digit, Atleast 1 special character | E36: =IF(OR(OR(AND('Asset Info'!B5="Desktop",F7="Yes"),'Asset Info'!B5="Code based library"),'Asset Info'!B5="APIs Only"),"No",IF(OR(E37="Yes",F38="Yes"),"No","Yes")) -> Yes | G36: =IF(ISBLANK(F36),"",IF(F36="Yes","Password Policy is configurable for min and max length and it contains atleast 1 special charcater, 1 digit, 1 upper case and 1 lower case character. It will not allow to set last 5 passwords and force the user to reset the password periodically.","Recommend to have password policy as configurable with min and max characters, 1 special character, 1 digit, atleast 1 upper case and 1 lower case letter. It should not allow to set last 5 passwords and force the user to reset the password periodically.")) | J36: =IF($F36="Yes","Y","N") -> N
C37: 2 | D37: NA | E37: =IF(OR(OR(AND('Asset Info'!B5="Desktop",F7="Yes"),'Asset Info'!B5="Code based library"),'Asset Info'!B5="APIs Only"),"No",IF(F7="Yes","Yes","No")) -> No | G37: =IF(AND('Asset Info'!B5="Desktop",F7="Yes"),"Application has no user registration module and is available as Desktop Application without user authentication.",IF('Asset Info'!B5="Code based library","Application is a code based library and do not have any user authentication",IF(AND('Asset Info'!B5="APIs Only",F17="Yes"),"API based application using API keys or authentication tokens for authenticating users or applications",IF(AND('Asset Info'!B5="APIs Only",F16="Yes"),"API based application used as a middle layer without API keys or authentication tokens",IF(AND('Asset Info'!B5="APIs Only",F20="Yes"),"API based application",IF(AND(F7="Yes",E37="Yes"),"Application does not have user registration module and connect to customer LDAP/IDM/SSO to identify and authenticate the user.","")))))) | J37: =IF(OR(OR(AND('Asset Info'!B5="Desktop",F7="Yes"),'Asset Info'!B5="Code based library"),'Asset Info'!B5="APIs Only"),"NA",IF(AND('Asset Info'!B5="Web/Mobile",F7="Yes"),"Y","N")) -> N
C38: 3 | D38: Others | E38: =IF(OR(OR(AND('Asset Info'!B5="Desktop",F7="Yes"),'Asset Info'!B5="Code based library"),'Asset Info'!B5="APIs Only"),"No",IF(OR(F36="Yes",E37="Yes"),"No","Yes")) -> Yes | J38: N | K38: =IF(AND($F38="Yes",ISBLANK($H38)),"Please enter your comments","")
A39: 5 | B39: Authentication Methods (One-way, Multi-factor etc.) | C39: 1 | D39: =IF('Asset Info'!B9="Internet",IF('Asset Info'!B5="Desktop","Does the application validates username and password for authentication?","Does the application has two-factor authentication?That is after validating the usename and password, does the application accepts OTP or any token using authenticator apps?"),"Does the application validates username and password for authentication?") -> Does the application validates username and password for authentication? | E39: =IF(OR(AND('Asset Info'!B5="Desktop",F7="Yes"),'Asset Info'!B5="APIs Only"),"No","Yes") -> Yes | G39: =IF(ISBLANK(F39),"",IF(AND('Asset Info'!B9="Internet",F39="Yes"),"Application is internet facing and has two-factor authentication enabled.",IF(AND('Asset Info'!B9="Internet",F39="No"),"Application has one-way authentication. Recommend to implement two-factor authentication as the application is internet facing.",IF(AND('Asset Info'!B9="Intranet",F39="Yes"),"Application has one-way authentication enabled","Recommend to enable one-way authentication")))) | J39: =IF($F39="Yes","Y","N") -> N
C40: 2 | D40: =IF(OR(OR(AND('Asset Info'!B5="Desktop",F7="Yes"),'Asset Info'!B5="Code based library"),'Asset Info'!B5="APIs Only"),"NA","Others") -> Others | E40: =IF(D40="NA","No","Yes") -> Yes | G40: =IF(AND('Asset Info'!B5="Desktop",F7="Yes"),"Application has no user registration module and is available as Desktop Application without user authentication.",IF('Asset Info'!B5="Code based library","Application is a code based library and do not have any user authentication",IF(AND('Asset Info'!B5="APIs Only",F17="Yes"),"API based application using API keys or authentication tokens for authenticating users or applications",IF(AND('Asset Info'!B5="APIs Only",F16="Yes"),"API based application used as a middle layer without API keys or authentication tokens",IF(AND('Asset Info'!B5="APIs Only",F20="Yes"),"API based application",IF(AND(F16="Yes",E40="Yes"),"Application does not have user registration module and connect to customer LDAP/IDM/SSO to identify and authenticate the user.","")))))) | J40: =IF(D40="NA","NA","N") -> N
A41: 6 | B41: Storage of credential | C41: 1 | D41: Does the application store user crendentials in DB by salting and hashing it? | E41: =IF(OR(OR(AND('Asset Info'!B5="Desktop",F7="Yes"),'Asset Info'!B5="Code based library"),'Asset Info'!B5="APIs Only"),"No",IF(OR(E42="Yes",F43="Yes"),"No","Yes")) -> Yes | J41: =IF(J44="N","N","Y") -> N
...

Sheet Report
A1: Asset TIPAR ID | B1: ='Asset Info'!B2 -> 0
A2: QOPD Evaluation Status | B2: =IF(COUNTIF(C10:C69,"Not Approved")>0,"Not Cleared","Cleared") -> Not Cleared
A3: Reviewer Evaluation Status
A4: Reviewer Final Comments
A6: Total Applicable Checklist Items | B6: =SUM(B7:B8) -> 60
A7: Total Autoapproved | B7: =COUNTIF(C11:C70,"Approved") -> 0
A8: Total Not Autoapproved | B8: =COUNTIF(C11:C70,"Not Approved") -> 60
A10: Security Foundation Parameter | B10: Checklist category | C10: Approval Status
A11: Authentication | B11: User Registration | C11: =IF(COUNTIF(Checklist!J5:'Checklist'!J20,"NA")>0,"Not Applicable",IF(COUNTIF(Checklist!J5:'Checklist'!J20,"Y")>0,"Approved","Not Approved")) -> Not Approved
B12: User identification and authentication | C12: =IF(COUNTIF(Checklist!J21:'Checklist'!J23,"NA")>0,"Not Applicable",IF(COUNTIF(Checklist!J21:'Checklist'!J23,"Y")>0,"Approved","Not Approved")) -> Not Approved
B13: User password management | C13: =IF(COUNTIF(Checklist!J24:'Checklist'!J35,"NA")>0,"Not Applicable",IF(COUNTIF(Checklist!J24:'Checklist'!J35,"Y")>0,"Approved","Not Approved")) -> Not Approved
B14: Password policy | C14: =IF(COUNTIF(Checklist!J36:'Checklist'!J38,"NA")>0,"Not Applicable",IF(COUNTIF(Checklist!J36:'Checklist'!J38,"Y")>0,"Approved","Not Approved")) -> Not Approved
B15: Authentication Methods (One-way, Multi-factor etc.) | C15: =IF(COUNTIF(Checklist!J39:'Checklist'!J40,"NA")>0,"Not Applicable",IF(COUNTIF(Checklist!J39:'Checklist'!J40,"Y")>0,"Approved","Not Approved")) -> Not Approved
B16: Storage of credential | C16: =IF(COUNTIF(Checklist!J41:'Checklist'!J45,"NA")>0,"Not Applicable",IF(COUNTIF(Checklist!J41:'Checklist'!J45,"Y")>0,"Approved","Not Approved")) -> Not Approved
B17: Storage of any other authentication secret | C17: =IF(COUNTIF(Checklist!J46:'Checklist'!J48,"NA")>0,"Not Applicable",IF(COUNTIF(Checklist!J46:'Checklist'!J48,"Y")>0,"Approved","Not Approved")) -> Not Approved
B18: User enumeration | C18: =IF(COUNTIF(Checklist!J49:'Checklist'!J51,"NA")>0,"Not Applicable",IF(COUNTIF(Checklist!J49:'Checklist'!J51,"Y")>0,"Approved","Not Approved")) -> Not Approved
B19: Default or guessable user account or credentials | C19: =IF(COUNTIF(Checklist!J52:'Checklist'!J53,"NA")>0,"Not Applicable",IF(COUNTIF(Checklist!J52:'Checklist'!J53,"Y")>0,"Approved","Not Approved")) -> Not Approved
B20: Account lockout and reopening | C20: =IF(COUNTIF(Checklist!J54:'Checklist'!J59,"NA")>0,"Not Applicable",IF(COUNTIF(Checklist!J54:'Checklist'!J59,"Y")>0,"Approved","Not Approved")) -> Not Approved
B21: Brute force login Attack | C21: =IF(COUNTIF(Checklist!J60:'Checklist'!J62,"NA")>0,"Not Applicable",IF(COUNTIF(Checklist!J60:'Checklist'!J62,"Y")>0,"Approved","Not Approved")) -> Not Approved
B22: Bypassing authentication schema | C22: =IF(COUNTIF(Checklist!J63:'Checklist'!J65,"NA")>0,"Not Applicable",IF(COUNTIF(Checklist!J63:'Checklist'!J65,"Y")>0,"Approved","Not Approved")) -> Not Approved
B23: Logout and Browser Cache management | C23: =IF(COUNTIF(Checklist!J66:'Checklist'!J70,"NA")>0,"Not Applicable",IF(COUNTIF(Checklist!J66:'Checklist'!J70,"Y")>0,"Approved","Not Approved")) -> Not Approved
B24: CAPTCHA | C24: =IF(COUNTIF(Checklist!J71:'Checklist'!J75,"NA")>0,"Not Applicable",IF(COUNTIF(Checklist!J71:'Checklist'!J75,"Y")>0,"Approved","Not Approved")) -> Not Approved
B25: Profile Cloning | C25: =IF(COUNTIF(Checklist!J76:'Checklist'!J77,"NA")>0,"Not Applicable",IF(COUNTIF(Checklist!J76:'Checklist'!J77,"Y")>0,"Approved","Not Approved")) -> Not Approved
A26: Authorization | B26: User Access and Privilege management | C26: =IF(COUNTIF(Checklist!J79:'Checklist'!J82,"NA")>0,"Not Applicable",IF(COUNTIF(Checklist!J79:'Checklist'!J82,"Y")>0,"Approved","Not Approved")) -> Not Approved
B27: Grant of access to systems and business applications | C27: =IF(COUNTIF(Checklist!J83:'Checklist'!J84,"NA")>0,"Not Applicable",IF(COUNTIF(Checklist!J83:'Checklist'!J84,"Y")>0,"Approved","Not Approved")) -> Not Approved
B28: Non Predictable Session Identifier or tokens | C28: =IF(COUNTIF(Checklist!J85:'Checklist'!J86,"NA")>0,"Not Applicable",IF(COUNTIF(Checklist!J85:'Checklist'!J86,"Y")>0,"Approved","Not Approved")) -> Not Approved
B29: Session or token time-out | C29: =IF(COUNTIF(Checklist!J87:'Checklist'!J89,"NA")>0,"Not Applicable",IF(COUNTIF(Checklist!J87:'Checklist'!J89,"Y")>0,"Approved","Not Approved")) -> Not Approved
B30: Restricted File access | C30: =IF(COUNTIF(Checklist!J90:'Checklist'!J92,"NA")>0,"Not Applicable",IF(COUNTIF(Checklist!J90:'Checklist'!J92,"Y")>0,"Approved","Not Approved")) -> Not Approved
B31: Path traversal | C31: =IF(COUNTIF(Checklist!J93:'Checklist'!J95,"NA")>0,"Not Applicable",IF(COUNTIF(Checklist!J93:'Checklist'!J95,"Y")>0,"Approved","Not Approved")) -> Not Approved
B32: Horizontal privilege escalation | C32: =IF(COUNTIF(Checklist!J96:'Checklist'!J97,"NA")>0,"Not Applicable",IF(COUNTIF(Checklist!J96:'Checklist'!J97,"Y")>0,"Approved","Not Approved")) -> Not Approved
B33: Vertical privilege escalation | C33: =IF(COUNTIF(Checklist!J98:'Checklist'!J99,"NA")>0,"Not Applicable",IF(COUNTIF(Checklist!J98:'Checklist'!J99,"Y")>0,"Approved","Not Approved")) -> Not Approved
B34: Session Identifier/token storage | C34: =IF(COUNTIF(Checklist!J100:'Checklist'!J104,"NA")>0,"Not Applicable",IF(COUNTIF(Checklist!J100:'Checklist'!J104,"Y")>0,"Approved","Not Approved")) -> Not Approved
B35: Cookie Attributes | C35: =IF(COUNTIF(Checklist!J105:'Checklist'!J107,"NA")>0,"Not Applicable",IF(COUNTIF(Checklist!J105:'Checklist'!J107,"Y")>0,"Approved","Not Approved")) -> Not Approved
B36: Session Fixation | C36: =IF(COUNTIF(Checklist!J108:'Checklist'!J109,"NA")>0,"Not Applicable",IF(COUNTIF(Checklist!J108:'Checklist'!J109,"Y")>0,"Approved","Not Approved")) -> Not Approved
A37: Confidentiality | B37: Electronic messaging | C37: =IF(COUNTIF(Checklist!J111:'Checklist'!J113,"NA")>0,"Not Applicable",IF(COUNTIF(Checklist!J111:'Checklist'!J113,"Y")>0,"Approved","Not Approved")) -> Not Approved
B38: Access Control to code - Program source code | C38: =IF(COUNTIF(Checklist!J114:'Checklist'!J116,"NA")>0,"Not Applicable",IF(COUNTIF(Checklist!J114:'Checklist'!J116,"Y")>0,"Approved","Not Approved")) -> Not Approved
B39: Access Control to data - Sensitive data - Processing and storage data | C39: =IF(COUNTIF(Checklist!J117:'Checklist'!J117,"NA")>0,"Not Applicable",IF(COUNTIF(Checklist!J117:'Checklist'!J117,"Y")>0,"Approved","Not Approved")) -> Not Approved
B40: Data security in transit | C40: =IF(COUNTIF(Checklist!J118:'Checklist'!J119,"NA")>0,"Not Applicable",IF(COUNTIF(Checklist!J118:'Checklist'!J119,"Y")>0,"Approved","Not Approved")) -> Not Approved
B41: Data security in storage | C41: =IF(COUNTIF(Checklist!J120:'Checklist'!J121,"NA")>0,"Not Applicable",IF(COUNTIF(Checklist!J120:'Checklist'!J121,"Y")>0,"Approved","Not Approved")) -> Not Approved
B42: Key Management | C42: =IF(COUNTIF(Checklist!J1122:'Checklist'!J75,"NA")>0,"Not Applicable",IF(COUNTIF(Checklist!J122:'Checklist'!J124,"Y")>0,"Approved","Not Approved")) -> Not Approved
...
